<?xml version="1.0"?>
<robot name="robot">


    <link name="base_link" > 
        <visual>
            <origin rpy="1.57 0 0" xyz="0 0 0"/>
            <geometry>
              <mesh filename="file://$(find robot_bringup)/robot_mesh/base_link.dae"/> 
            </geometry>
          </visual>
    </link >

    <link name="link1">
      <visual>
        <origin rpy="1.57 0 1.57" xyz="0 0 0"/>
        <geometry>
          <mesh filename="file://$(find robot_bringup)/robot_mesh/link1.dae"/> 
        </geometry>
      </visual>
    </link >

    <link name="link2" >
      <visual>
        <origin rpy="-1.57 0 3.14" xyz="0 0 0"/>
        <geometry>
          <mesh filename="file://$(find robot_bringup)/robot_mesh/link2.dae"/> 
        </geometry>
      </visual>
    </link >

    <link name="link3" >
      <visual>
        <origin rpy="1.57 0 3.14" xyz="0 0 0"/>
        <geometry>
          <mesh filename="file://$(find robot_bringup)/robot_mesh/link3.dae"/> 
        </geometry>
      </visual>
    </link >

    <link name="link4_artificial" >
    </link >

    <link name="link4" >
      <visual>
        <origin rpy="3.14 1.57 0" xyz="0 0 0"/>
        <geometry>
          <mesh filename="file://$(find robot_bringup)/robot_mesh/link4.dae"/> 
        </geometry>
      </visual>
    </link >

    <link name="link5" >
    </link >


    <!-- Joints Declaration -->
    <joint name="joint1" type="revolute">
      <parent link="base_link"/>
      <child link="link1"/>
      <axis xyz="0 0 1" />
      <origin xyz="0 0 0.2645" rpy="0 0 0" />
    </joint>
  
    <joint name="joint2" type="revolute">
      <parent link="link1"/>
      <child link="link2"/>
      <axis xyz="0 0 1" />
      <origin xyz="0.21938 0.1675 0.332" rpy="1.57 0 0" />
    </joint>
  
    <joint name="joint3" type="revolute">
      <parent link="link2"/>
      <child link="link3"/>
      <axis xyz="0 0 1" />
      <origin xyz="0 1.100 0" rpy="0 0 0" />
    </joint>

    <joint name="joint4_artificial" type="revolute">
      <mimic joint="joint2" multiplier="-1" offset="0" />
      <parent link="link3"/>
      <child link="link4_artificial"/>
      <axis xyz="0 0 1" />
      <origin xyz="0.97509 0 0.1025" rpy="0 0 0" />
    </joint>

    <joint name="joint4" type="revolute">
      <mimic joint="joint3" multiplier="-1" offset="0" />
      <parent link="link4_artificial"/>
      <child link="link4"/>
      <axis xyz="0 0 1" />
      <origin xyz="0 0 0" rpy="0 0 0" />
    </joint>

    <joint name="joint5" type="revolute">
      <parent link="link4"/>
      <child link="link5"/>
      <axis xyz="0 0 1" />
      <origin xyz="0.1718 -0.18957 0" rpy="1.57 0 0" />
    </joint>



  </robot>